Workbook

Sheet Working
A2: Category | B2: Venue | C2: No of courts | D2: Teams | E2: Est Time (in mins) | F2: Total matches | G2: Total Time (in hrs) | H2: 05th | I2: 11th | J2: 12th | K2: Court charges | M2: Teams
A3: Open Women's Doubles | B3: GB | C3: 3 | D3: 12 | E3: 13 | F3: 24 | G3: =(F3*E3)/60/C3 -> 1.7333333 | H3: ☑ | K3: 400 | M3: No of matches calculation | N3: 32 | O3: 28 | P3: 24 | Q3: 16 | R3: 12
A4: 45+ Split Doubles | B4: GB | C4: 3 | D4: 24 | E4: =E3 -> 13 | F4: 48 | G4: =(F4*E4)/60/C4 -> 3.4666667 | H4: ☑ | K4: =K3 -> 400 | N4: =N3/4 -> 8 | O4: =O3/4 -> 7 | P4: =P3/4 -> 6 | Q4: =Q3/4 -> 4 | R4: =R3/4 -> 3
A5: Beginner Men's Doubles | B5: GB | C5: 3 | D5: 32 | E5: =E4 -> 13 | F5: 63 | G5: =(F5*E5)/60/C5 -> 4.55 | H5: ☑ | K5: =K4 -> 400 | N5: =N4*6 -> 48 | O5: =O4*6 -> 42 | P5: =P4*6 -> 36 | Q5: =Q4*6 -> 24 | R5: =R4*6 -> 18
A6: Beginner Mixed Doubles | B6: GB | C6: 3 | D6: 24 | E6: =E5 -> 13 | F6: 48 | G6: =(F6*E6)/60/C6 -> 3.4666667 | H6: ☑ | K6: =K5 -> 400 | N6: 8 | O6: 7 | P6: 6 | Q6: 4 | R6: 3
A7: Intermediate Men's Doubles | B7: Adda | C7: 2 | D7: 32 | E7: =E6 -> 13 | F7: 63 | G7: =(F7*E7)/60/C7 -> 6.825 | I7: ☑ | K7: 600 | N7: 4 | O7: 4 | P7: 3 | Q7: 2 | R7: 2
A8: Intermediate 35+ Split Doubles | B8: Adda | C8: 2 | D8: 12 | E8: =E7 -> 13 | F8: 24 | G8: =(F8*E8)/60/C8 -> 2.6 | I8: ☑ | K8: 600 | N8: 2 | O8: 2 | P8: 2 | Q8: 1 | R8: 1
A9: Open Men's Singles | B9: Adda | C9: 2 | D9: 24 | E9: 10 | F9: 48 | G9: =(F9*E9)/60/C9 -> 4 | I9: ☑ | K9: =K7 -> 600 | N9: 1 | O9: 1 | P9: 1
A10: Open Mixed Doubles | B10: Adda | C10: 2 | D10: 24 | E10: =E7 -> 13 | F10: =D10*2 -> 48 | G10: =(F10*E10)/60/C10 -> 5.2 | J10: ☑ | K10: =K9 -> 600
A11: Advanced Men's Doubles | B11: Adda | C11: 2 | D11: 24 | E11: 16 | F11: 48 | G11: =(F11*E11)/60/C11 -> 6.4 | J11: ☑ | K11: =K10 -> 600
A14: GB PnL
A16: Income: | C16: 1600
A17: Open Women's Doubles | B17: =D3 -> 12 | C17: =$B17*C$16 -> 19200
A18: 45+ Split Doubles | B18: =D4 -> 24 | C18: =$B18*C$16 -> 38400
A19: Beginner Men's Doubles | B19: =D5 -> 32 | C19: =$B19*C$16 -> 51200
A20: Beginner Mixed Doubles | B20: =D6 -> 24 | C20: =$B20*C$16 -> 38400
A21: Fee income | C21: =SUM(C17:C20) -> 147200
A23: Expense:
A24: Court charges | C24: =SUM(G3:G6)*C3*K3 -> 15860
A25: Ref fees | C25: =1500*3 -> 4500
A26: Ball cost (Ash100) | C26: =100*10 -> 1000
A27: Prize Pool | C27: =SUM(B71:E71) -> 12000
A28: F&B (tea & snacks) | C28: =50*100 -> 5000
A29: Live stream (3 courts) | C29: 18000
A30: Misc | C30: 15000
A31: Total expense | C31: =SUM(C24:C30) -> 71360
A33: Total Profit | C33: =C21-C31 -> 75840
A35: Adda PnL
A36: Income: | C36: Case 1
A37: Adv Doubles | C37: 2200
A38: Doubles | C38: 2000
A39: Singles | C39: 1000
A40: Intermediate Men's Doubles | B40: =D7 -> 32 | C40: =C$38*$B40 -> 64000
A41: Intermediate 35+ Split Doubles | B41: 12 | C41: =C$38*$B41 -> 24000
A42: Open Men's Singles | B42: =D9 -> 24 | C42: =C$39*$B42 -> 24000
A43: Open Mixed Doubles | B43: =D10 -> 24 | C43: =C$38*$B43 -> 48000
A44: Advanced Men's Doubles | B44: =D11 -> 24 | C44: =C$38*$B44 -> 48000
A45: Other income | C45: 30000
A46: Total income | C46: =SUM(C40:C45) -> 238000
A48: Expense:
...

Sheet Registrations
A1: Registrations Input (Enter names here; Schedule auto-updates)
A3: Category | B3: Code | C3: Player 1 | D3: Player 2 | E3: Team ID | F3: UPI ID | G3: Player 1 DUPR | H3: Player 2 DUPR
A4: Open Men Singles | B4: MS01 | C4: Sanjay Gatti | E4: =IF(Registrations[[#This Row],[Player 2]]="",Registrations[[#This Row],[Player 1]],Registrations[[#This Row],[Player 1]]&" / "&Registrations[[#This Row],[Player 2]]) -> Sanjay Gatti | F4: 606469989512
A5: Open Men Singles | B5: MS02 | E5: =IF(Registrations[[#This Row],[Player 2]]="",Registrations[[#This Row],[Player 1]],Registrations[[#This Row],[Player 1]]&" / "&Registrations[[#This Row],[Player 2]]) -> 0
A6: Open Men Singles | B6: MS03 | E6: =IF(Registrations[[#This Row],[Player 2]]="",Registrations[[#This Row],[Player 1]],Registrations[[#This Row],[Player 1]]&" / "&Registrations[[#This Row],[Player 2]]) -> 0
A7: Open Men Singles | B7: MS04 | E7: =IF(Registrations[[#This Row],[Player 2]]="",Registrations[[#This Row],[Player 1]],Registrations[[#This Row],[Player 1]]&" / "&Registrations[[#This Row],[Player 2]]) -> 0
A8: Open Men Singles | B8: MS05 | E8: =IF(Registrations[[#This Row],[Player 2]]="",Registrations[[#This Row],[Player 1]],Registrations[[#This Row],[Player 1]]&" / "&Registrations[[#This Row],[Player 2]]) -> 0
A9: Open Men Singles | B9: MS06 | E9: =IF(Registrations[[#This Row],[Player 2]]="",Registrations[[#This Row],[Player 1]],Registrations[[#This Row],[Player 1]]&" / "&Registrations[[#This Row],[Player 2]]) -> 0
A10: Open Men Singles | B10: MS07 | E10: =IF(Registrations[[#This Row],[Player 2]]="",Registrations[[#This Row],[Player 1]],Registrations[[#This Row],[Player 1]]&" / "&Registrations[[#This Row],[Player 2]]) -> 0
A11: Open Men Singles | B11: MS08 | E11: =IF(Registrations[[#This Row],[Player 2]]="",Registrations[[#This Row],[Player 1]],Registrations[[#This Row],[Player 1]]&" / "&Registrations[[#This Row],[Player 2]]) -> 0
A12: Open Men Singles | B12: MS09 | E12: =IF(Registrations[[#This Row],[Player 2]]="",Registrations[[#This Row],[Player 1]],Registrations[[#This Row],[Player 1]]&" / "&Registrations[[#This Row],[Player 2]]) -> 0
A13: Open Men Singles | B13: MS10 | E13: =IF(Registrations[[#This Row],[Player 2]]="",Registrations[[#This Row],[Player 1]],Registrations[[#This Row],[Player 1]]&" / "&Registrations[[#This Row],[Player 2]]) -> 0
A14: Open Men Singles | B14: MS11 | E14: =IF(Registrations[[#This Row],[Player 2]]="",Registrations[[#This Row],[Player 1]],Registrations[[#This Row],[Player 1]]&" / "&Registrations[[#This Row],[Player 2]]) -> 0
A15: Open Men Singles | B15: MS12 | E15: =IF(Registrations[[#This Row],[Player 2]]="",Registrations[[#This Row],[Player 1]],Registrations[[#This Row],[Player 1]]&" / "&Registrations[[#This Row],[Player 2]]) -> 0
A16: Open Men Singles | B16: MS13 | E16: =IF(Registrations[[#This Row],[Player 2]]="",Registrations[[#This Row],[Player 1]],Registrations[[#This Row],[Player 1]]&" / "&Registrations[[#This Row],[Player 2]]) -> 0
... A119: Adv Men Doubles | B119: AMD24 | E119: =IF(Registrations[[#This Row],[Player 2]]="",Registrations[[#This Row],[Player 1]],Registrations[[#This Row],[Player 1]]&" / "&Registrations[[#This Row],[Player 2]]) -> 0
A120: 45+ Split Doubles | B120: SD4501 | C120: Rajib Sengupta | D120: Antriksh Gala | E120: =IF(Registrations[[#This Row],[Player 2]]="",Registrations[[#This Row],[Player 1]],Registrations[[#This Row],[Player 1]]&" / "&Registrations[[#This Row],[Player 2]]) -> Rajib Sengupta / Antriksh Gala | F120: 643027306079
A121: 45+ Split Doubles | B121: SD4502 | C121: Pratik Bhagat | D121: Godfrey Kattancherry | E121: =IF(Registrations[[#This Row],[Player 2]]="",Registrations[[#This Row],[Player 1]],Registrations[[#This Row],[Player 1]]&" / "&Registrations[[#This Row],[Player 2]]) -> Pratik Bhagat / Godfrey Kattancherry | F121: 119739308747
A122: 45+ Split Doubles | B122: SD4503 | E122: =IF(Registrations[[#This Row],[Player 2]]="",Registrations[[#This Row],[Player 1]],Registrations[[#This Row],[Player 1]]&" / "&Registrations[[#This Row],[Player 2]]) -> 0
A123: 45+ Split Doubles | B123: SD4504 | E123: =IF(Registrations[[#This Row],[Player 2]]="",Registrations[[#This Row],[Player 1]],Registrations[[#This Row],[Player 1]]&" / "&Registrations[[#This Row],[Player 2]]) -> 0
A124: 45+ Split Doubles | B124: SD4505 | E124: =IF(Registrations[[#This Row],[Player 2]]="",Registrations[[#This Row],[Player 1]],Registrations[[#This Row],[Player 1]]&" / "&Registrations[[#This Row],[Player 2]]) -> 0
A125: 45+ Split Doubles | B125: SD4506 | E125: =IF(Registrations[[#This Row],[Player 2]]="",Registrations[[#This Row],[Player 1]],Registrations[[#This Row],[Player 1]]&" / "&Registrations[[#This Row],[Player 2]]) -> 0
A126: 45+ Split Doubles | B126: SD4507 | E126: =IF(Registrations[[#This Row],[Player 2]]="",Registrations[[#This Row],[Player 1]],Registrations[[#This Row],[Player 1]]&" / "&Registrations[[#This Row],[Player 2]]) -> 0
A127: 45+ Split Doubles | B127: SD4508 | E127: =IF(Registrations[[#This Row],[Player 2]]="",Registrations[[#This Row],[Player 1]],Registrations[[#This Row],[Player 1]]&" / "&Registrations[[#This Row],[Player 2]]) -> 0
A128: 45+ Split Doubles | B128: SD4509 | E128: =IF(Registrations[[#This Row],[Player 2]]="",Registrations[[#This Row],[Player 1]],Registrations[[#This Row],[Player 1]]&" / "&Registrations[[#This Row],[Player 2]]) -> 0
A129: 45+ Split Doubles | B129: SD4510 | E129: =IF(Registrations[[#This Row],[Player 2]]="",Registrations[[#This Row],[Player 1]],Registrations[[#This Row],[Player 1]]&" / "&Registrations[[#This Row],[Player 2]]) -> 0
A130: 45+ Split Doubles | B130: SD4511 | E130: =IF(Registrations[[#This Row],[Player 2]]="",Registrations[[#This Row],[Player 1]],Registrations[[#This Row],[Player 1]]&" / "&Registrations[[#This Row],[Player 2]]) -> 0
A131: 45+ Split Doubles | B131: SD4512 | E131: =IF(Registrations[[#This Row],[Player 2]]="",Registrations[[#This Row],[Player 1]],Registrations[[#This Row],[Player 1]]&" / "&Registrations[[#This Row],[Player 2]]) -> 0
A132: 45+ Split Doubles | B132: SD4513 | E132: =IF(Registrations[[#This Row],[Player 2]]="",Registrations[[#This Row],[Player 1]],Registrations[[#This Row],[Player 1]]&" / "&Registrations[[#This Row],[Player 2]]) -> 0
A133: 45+ Split Doubles | B133: SD4514 | E133: =IF(Registrations[[#This Row],[Player 2]]="",Registrations[[#This Row],[Player 1]],Registrations[[#This Row],[Player 1]]&" / "&Registrations[[#This Row],[Player 2]]) -> 0
... A143: 45+ Split Doubles | B143: SD4524 | E143: =IF(Registrations[[#This Row],[Player 2]]="",Registrations[[#This Row],[Player 1]],Registrations[[#This Row],[Player 1]]&" / "&Registrations[[#This Row],[Player 2]]) -> 0
A144: Beginner Men's Doubles | B144: BMD01 | C144: Sanjay Gatti | D144: Prabhakar Ghadge | E144: =IF(Registrations[[#This Row],[Player 2]]="",Registrations[[#This Row],[Player 1]],Registrations[[#This Row],[Player 1]]&" / "&Registrations[[#This Row],[Player 2]]) -> Sanjay Gatti / Prabhakar Ghadge
A145: Beginner Men's Doubles | B145: BMD02 | C145: Yash Salvi | D145: Chaitanya Hirlekar | E145: =IF(Registrations[[#This Row],[Player 2]]="",Registrations[[#This Row],[Player 1]],Registrations[[#This Row],[Player 1]]&" / "&Registrations[[#This Row],[Player 2]]) -> Yash Salvi / Chaitanya Hirlekar | F145: 606706698051 | G145: ZDXQQW | H145: XKPMX7
A146: Beginner Men's Doubles | B146: BMD03 | E146: =IF(Registrations[[#This Row],[Player 2]]="",Registrations[[#This Row],[Player 1]],Registrations[[#This Row],[Player 1]]&" / "&Registrations[[#This Row],[Player 2]]) -> 0
A147: Beginner Men's Doubles | B147: BMD04 | E147: =IF(Registrations[[#This Row],[Player 2]]="",Registrations[[#This Row],[Player 1]],Registrations[[#This Row],[Player 1]]&" / "&Registrations[[#This Row],[Player 2]]) -> 0
A148: Beginner Men's Doubles | B148: BMD05 | E148: =IF(Registrations[[#This Row],[Player 2]]="",Registrations[[#This Row],[Player 1]],Registrations[[#This Row],[Player 1]]&" / "&Registrations[[#This Row],[Player 2]]) -> 0
A149: Beginner Men's Doubles | B149: BMD06 | E149: =IF(Registrations[[#This Row],[Player 2]]="",Registrations[[#This Row],[Player 1]],Registrations[[#This Row],[Player 1]]&" / "&Registrations[[#This Row],[Player 2]]) -> 0
A150: Beginner Men's Doubles | B150: BMD07 | E150: =IF(Registrations[[#This Row],[Player 2]]="",Registrations[[#This Row],[Player 1]],Registrations[[#This Row],[Player 1]]&" / "&Registrations[[#This Row],[Player 2]]) -> 0
A151: Beginner Men's Doubles | B151: BMD08 | E151: =IF(Registrations[[#This Row],[Player 2]]="",Registrations[[#This Row],[Player 1]],Registrations[[#This Row],[Player 1]]&" / "&Registrations[[#This Row],[Player 2]]) -> 0
A152: Beginner Men's Doubles | B152: BMD09 | E152: =IF(Registrations[[#This Row],[Player 2]]="",Registrations[[#This Row],[Player 1]],Registrations[[#This Row],[Player 1]]&" / "&Registrations[[#This Row],[Player 2]]) -> 0
...

Sheet Groups
A1: Category | B1: Pool 1 | C1: ="Pool " & VALUE(RIGHT(B1, LEN(B1)-5))+1 -> Pool 2 | D1: ="Pool " & VALUE(RIGHT(C1, LEN(C1)-5))+1 -> Pool 3 | E1: ="Pool " & VALUE(RIGHT(D1, LEN(D1)-5))+1 -> Pool 4 | F1: ="Pool " & VALUE(RIGHT(E1, LEN(E1)-5))+1 -> Pool 5 | G1: ="Pool " & VALUE(RIGHT(F1, LEN(F1)-5))+1 -> Pool 6 | H1: ="Pool " & VALUE(RIGHT(G1, LEN(G1)-5))+1 -> Pool 7 | I1: ="Pool " & VALUE(RIGHT(H1, LEN(H1)-5))+1 -> Pool 8
A2: Open Men Singles | B2: ='Registrations'!E4 -> Sanjay Gatti | C2: ='Registrations'!E8 -> 0 | D2: ='Registrations'!E12 -> 0 | E2: ='Registrations'!E16 -> 0 | F2: ='Registrations'!E20 -> 0 | G2: ='Registrations'!E24 -> 0
B3: ='Registrations'!E5 -> 0 | C3: ='Registrations'!E9 -> 0 | D3: ='Registrations'!E13 -> 0 | E3: ='Registrations'!E17 -> 0 | F3: ='Registrations'!E21 -> 0 | G3: ='Registrations'!E25 -> 0
B4: ='Registrations'!E6 -> 0 | C4: ='Registrations'!E10 -> 0 | D4: ='Registrations'!E14 -> 0 | E4: ='Registrations'!E18 -> 0 | F4: ='Registrations'!E22 -> 0 | G4: ='Registrations'!E26 -> 0
B5: ='Registrations'!E7 -> 0 | C5: ='Registrations'!E11 -> 0 | D5: ='Registrations'!E15 -> 0 | E5: ='Registrations'!E19 -> 0 | F5: ='Registrations'!E23 -> 0 | G5: ='Registrations'!E27 -> 0
A7: Intermediate 35+ Split Doubles | B7: ='Registrations'!E28 -> 0 | C7: ='Registrations'!E32 -> 0 | D7: ='Registrations'!E36 -> 0
B8: ='Registrations'!E29 -> 0 | C8: ='Registrations'!E33 -> 0 | D8: ='Registrations'!E37 -> 0
B9: ='Registrations'!E30 -> 0 | C9: ='Registrations'!E34 -> 0 | D9: ='Registrations'!E38 -> 0
B10: ='Registrations'!E31 -> 0 | C10: ='Registrations'!E35 -> 0 | D10: ='Registrations'!E39 -> 0
A12: Int Men Doubles | B12: ='Registrations'!E40 -> 0 | C12: ='Registrations'!E44 -> 0 | D12: ='Registrations'!E48 -> 0 | E12: ='Registrations'!E52 -> 0 | F12: ='Registrations'!E56 -> 0 | G12: ='Registrations'!E60 -> 0 | H12: ='Registrations'!E64 -> 0 | I12: ='Registrations'!E68 -> 0
B13: ='Registrations'!E41 -> 0 | C13: ='Registrations'!E45 -> 0 | D13: ='Registrations'!E49 -> 0 | E13: ='Registrations'!E53 -> 0 | F13: ='Registrations'!E57 -> 0 | G13: ='Registrations'!E61 -> 0 | H13: ='Registrations'!E65 -> 0 | I13: ='Registrations'!E69 -> 0
B14: ='Registrations'!E42 -> 0 | C14: ='Registrations'!E46 -> 0 | D14: ='Registrations'!E50 -> 0 | E14: ='Registrations'!E54 -> 0 | F14: ='Registrations'!E58 -> 0 | G14: ='Registrations'!E62 -> 0 | H14: ='Registrations'!E66 -> 0 | I14: ='Registrations'!E70 -> 0
B15: ='Registrations'!E43 -> 0 | C15: ='Registrations'!E47 -> 0 | D15: ='Registrations'!E51 -> 0 | E15: ='Registrations'!E55 -> 0 | F15: ='Registrations'!E59 -> 0 | G15: ='Registrations'!E63 -> 0 | H15: ='Registrations'!E67 -> 0 | I15: ='Registrations'!E71 -> 0
A17: Open Mixed Doubles | B17: ='Registrations'!E72 -> 0 | C17: ='Registrations'!E76 -> 0 | D17: ='Registrations'!E80 -> 0 | E17: ='Registrations'!E84 -> 0 | F17: ='Registrations'!E88 -> 0 | G17: ='Registrations'!E92 -> 0
B18: ='Registrations'!E73 -> 0 | C18: ='Registrations'!E77 -> 0 | D18: ='Registrations'!E81 -> 0 | E18: ='Registrations'!E85 -> 0 | F18: ='Registrations'!E89 -> 0 | G18: ='Registrations'!E93 -> 0
B19: ='Registrations'!E74 -> 0 | C19: ='Registrations'!E78 -> 0 | D19: ='Registrations'!E82 -> 0 | E19: ='Registrations'!E86 -> 0 | F19: ='Registrations'!E90 -> 0 | G19: ='Registrations'!E94 -> 0
B20: ='Registrations'!E75 -> 0 | C20: ='Registrations'!E79 -> 0 | D20: ='Registrations'!E83 -> 0 | E20: ='Registrations'!E87 -> 0 | F20: ='Registrations'!E91 -> 0 | G20: ='Registrations'!E95 -> 0
A22: Adv Men Doubles | B22: ='Registrations'!E96 -> 0 | C22: ='Registrations'!E100 -> 0 | D22: ='Registrations'!E104 -> 0 | E22: ='Registrations'!E108 -> 0 | F22: ='Registrations'!E112 -> 0 | G22: ='Registrations'!E116 -> 0
B23: ='Registrations'!E97 -> 0 | C23: ='Registrations'!E101 -> 0 | D23: ='Registrations'!E105 -> 0 | E23: ='Registrations'!E109 -> 0 | F23: ='Registrations'!E113 -> 0 | G23: ='Registrations'!E117 -> 0
B24: ='Registrations'!E98 -> 0 | C24: ='Registrations'!E102 -> 0 | D24: ='Registrations'!E106 -> 0 | E24: ='Registrations'!E110 -> 0 | F24: ='Registrations'!E114 -> 0 | G24: ='Registrations'!E118 -> 0
B25: ='Registrations'!E99 -> 0 | C25: ='Registrations'!E103 -> 0 | D25: ='Registrations'!E107 -> 0 | E25: ='Registrations'!E111 -> 0 | F25: ='Registrations'!E115 -> 0 | G25: ='Registrations'!E119 -> 0
A27: Open Women's Doubles | B27: ='Registrations'!E200 -> 0 | C27: ='Registrations'!E204 -> 0 | D27: ='Registrations'!E208 -> 0
B28: ='Registrations'!E201 -> 0 | C28: ='Registrations'!E205 -> 0 | D28: ='Registrations'!E209 -> 0
B29: ='Registrations'!E202 -> 0 | C29: ='Registrations'!E206 -> 0 | D29: ='Registrations'!E210 -> 0
B30: ='Registrations'!E203 -> 0 | C30: ='Registrations'!E207 -> 0 | D30: ='Registrations'!E211 -> 0
A32: 45+ Split Doubles | B32: ='Registrations'!E120 -> Rajib Sengupta / Antriksh Gala | C32: ='Registrations'!E124 -> 0 | D32: ='Registrations'!E128 -> 0 | E32: ='Registrations'!E132 -> 0 | F32: ='Registrations'!E136 -> 0 | G32: ='Registrations'!E140 -> 0
B33: ='Registrations'!E121 -> Pratik Bhagat / Godfrey Kattancherry | C33: ='Registrations'!E125 -> 0 | D33: ='Registrations'!E129 -> 0 | E33: ='Registrations'!E133 -> 0 | F33: ='Registrations'!E137 -> 0 | G33: ='Registrations'!E141 -> 0
B34: ='Registrations'!E122 -> 0 | C34: ='Registrations'!E126 -> 0 | D34: ='Registrations'!E130 -> 0 | E34: ='Registrations'!E134 -> 0 | F34: ='Registrations'!E138 -> 0 | G34: ='Registrations'!E142 -> 0
B35: ='Registrations'!E123 -> 0 | C35: ='Registrations'!E127 -> 0 | D35: ='Registrations'!E131 -> 0 | E35: ='Registrations'!E135 -> 0 | F35: ='Registrations'!E139 -> 0 | G35: ='Registrations'!E143 -> 0
A37: Beginner Men's Doubles | B37: ='Registrations'!E144 -> Sanjay Gatti / Prabhakar Ghadge | C37: ='Registrations'!E148 -> 0 | D37: ='Registrations'!E152 -> 0 | E37: ='Registrations'!E156 -> 0 | F37: ='Registrations'!E160 -> 0 | G37: ='Registrations'!E164 -> 0 | H37: ='Registrations'!E168 -> 0 | I37: ='Registrations'!E172 -> 0
B38: ='Registrations'!E145 -> Yash Salvi / Chaitanya Hirlekar | C38: ='Registrations'!E149 -> 0 | D38: ='Registrations'!E153 -> 0 | E38: ='Registrations'!E157 -> 0 | F38: ='Registrations'!E161 -> 0 | G38: ='Registrations'!E165 -> 0 | H38: ='Registrations'!E169 -> 0 | I38: ='Registrations'!E173 -> 0
B39: ='Registrations'!E146 -> 0 | C39: ='Registrations'!E150 -> 0 | D39: ='Registrations'!E154 -> 0 | E39: ='Registrations'!E158 -> 0 | F39: ='Registrations'!E162 -> 0 | G39: ='Registrations'!E166 -> 0 | H39: ='Registrations'!E170 -> 0 | I39: ='Registrations'!E174 -> 0
B40: ='Registrations'!E147 -> 0 | C40: ='Registrations'!E151 -> 0 | D40: ='Registrations'!E155 -> 0 | E40: ='Registrations'!E159 -> 0 | F40: ='Registrations'!E163 -> 0 | G40: ='Registrations'!E167 -> 0 | H40: ='Registrations'!E171 -> 0 | I40: ='Registrations'!E175 -> 0
A42: Beginner Mx Doubles | B42: ='Registrations'!E176 -> Sachin Verma / Hema Thakkar | C42: ='Registrations'!E180 -> 0 | D42: ='Registrations'!E184 -> 0 | E42: ='Registrations'!E188 -> 0 | F42: ='Registrations'!E192 -> 0 | G42: ='Registrations'!E196 -> 0
B43: ='Registrations'!E177 -> Amandeep Saini / Alisha Bhise | C43: ='Registrations'!E181 -> 0 | D43: ='Registrations'!E185 -> 0 | E43: ='Registrations'!E189 -> 0 | F43: ='Registrations'!E193 -> 0 | G43: ='Registrations'!E197 -> 0
B44: ='Registrations'!E178 -> Nachiket Gogia / Purva Verma | C44: ='Registrations'!E182 -> 0 | D44: ='Registrations'!E186 -> 0 | E44: ='Registrations'!E190 -> 0 | F44: ='Registrations'!E194 -> 0 | G44: ='Registrations'!E198 -> 0
B45: ='Registrations'!E179 -> 0 | C45: ='Registrations'!E183 -> 0 | D45: ='Registrations'!E187 -> 0 | E45: ='Registrations'!E191 -> 0 | F45: ='Registrations'!E195 -> 0 | G45: ='Registrations'!E199 -> 0

Sheet Input
A1: Open Men's Singles
A2: Group Stage | H2: Pre-Quarters | L2: Quarters | P2: Semis | T2: Finals
A3: Pool 1 | B3: {=TRANSPOSE(Groups!B2:B5)} -> Sanjay Gatti | C3: 0 | D3: 0 | E3: 0 | G3: Pool 1 vs 2 | H3: =B3 -> Sanjay Gatti | I3: =D4 -> 0 | K3: Pool 1 vs 6 | L3: =H3 -> Sanjay Gatti | M3: =H8 -> 0 | O3: Pool 1 vs 3 | P3: =L3 -> Sanjay Gatti | Q3: =L5 -> 0 | T3: =P3 -> Sanjay Gatti | U3: =P4 -> 0
A4: ="Pool " & VALUE(RIGHT(A3, LEN(A3)-5))+1 -> Pool 2 | B4: {=TRANSPOSE(Groups!C2:C5)} -> 0 | C4: 0 | D4: 0 | E4: 0 | G4: =G3 -> Pool 1 vs 2 | H4: =D3 -> 0 | I4: =B4 -> 0 | K4: Pool 2 vs 5 | L4: =H4 -> 0 | M4: =H7 -> 0 | O4: Pool 2 vs WC | P4: =L4 -> 0 | Q4: WC 01
A5: ="Pool " & VALUE(RIGHT(A4, LEN(A4)-5))+1 -> Pool 3 | B5: {=TRANSPOSE(Groups!D2:D5)} -> 0 | C5: 0 | D5: 0 | E5: 0 | G5: Pool 3 vs 4 | H5: =B5 -> 0 | I5: =D6 -> 0 | K5: Pool 3 vs 4 | L5: =H5 -> 0 | M5: =H6 -> 0
A6: ="Pool " & VALUE(RIGHT(A5, LEN(A5)-5))+1 -> Pool 4 | B6: {=TRANSPOSE(Groups!E2:E5)} -> 0 | C6: 0 | D6: 0 | E6: 0 | G6: =G5 -> Pool 3 vs 4 | H6: =D5 -> 0 | I6: =B6 -> 0
A7: ="Pool " & VALUE(RIGHT(A6, LEN(A6)-5))+1 -> Pool 5 | B7: {=TRANSPOSE(Groups!F2:F5)} -> 0 | C7: 0 | D7: 0 | E7: 0 | G7: Pool 5 vs 6 | H7: =B7 -> 0 | I7: =D8 -> 0
A8: ="Pool " & VALUE(RIGHT(A7, LEN(A7)-5))+1 -> Pool 6 | B8: {=TRANSPOSE(Groups!G2:G5)} -> 0 | C8: 0 | D8: 0 | E8: 0 | G8: =G7 -> Pool 5 vs 6 | H8: =D7 -> 0 | I8: =B8 -> 0
A9: ="Pool " & VALUE(RIGHT(A8, LEN(A8)-5))+1 -> Pool 7
A10: ="Pool " & VALUE(RIGHT(A9, LEN(A9)-5))+1 -> Pool 8
A12: Intermediate 35+ Split Doubles
A13: =A2 -> Group Stage | H13: Quarters | L13: Semis | P13: Finals
A14: =A3 -> Pool 1 | B14: {=TRANSPOSE(Groups!B7:B10)} -> 0 | C14: 0 | D14: 0 | E14: 0 | G14: Pool 1 vs 3 | H14: =B14 -> 0 | I14: =D16 -> 0 | K14: Pool 1 vs 2 | L14: =H14 -> 0 | M14: =H15 -> 0 | P14: =L14 -> 0 | Q14: =L15 -> 0
A15: =A4 -> Pool 2 | B15: {=TRANSPOSE(Groups!C7:C10)} -> 0 | C15: 0 | D15: 0 | E15: 0 | G15: Pool 2 vs 1 | H15: =B15 -> 0 | I15: =D14 -> 0 | K15: Pool 3 vs 4 | L15: =H16 -> 0 | M15: WC 1
A16: =A5 -> Pool 3 | B16: {=TRANSPOSE(Groups!D7:D10)} -> 0 | C16: 0 | D16: 0 | E16: 0 | G16: Pool 3 vs 2 | H16: =B16 -> 0 | I16: =D15 -> 0
A17: =A6 -> Pool 4
A18: =A7 -> Pool 5
A19: =A8 -> Pool 6
A20: =A9 -> Pool 7
A21: =A10 -> Pool 8
A23: Intermediate Men's Doubles
A24: =A13 -> Group Stage | H24: Pre-Quarters | L24: Quarters | P24: Semis | T24: Finals
A25: =A14 -> Pool 1 | B25: {=TRANSPOSE(Groups!B12:B15)} -> 0 | C25: 0 | D25: 0 | E25: 0 | G25: Pool 1 vs 2 | H25: =B25 -> 0 | I25: =D26 -> 0 | K25: Pool 1 vs 8 | L25: =H25 -> 0 | M25: =H32 -> 0 | O25: 1 vs 4 | P25: =L25 -> 0 | Q25: =L28 -> 0 | S25: 1 vs 2 | T25: =P25 -> 0 | U25: =P26 -> 0
A26: =A15 -> Pool 2 | B26: {=TRANSPOSE(Groups!C12:C15)} -> 0 | C26: 0 | D26: 0 | E26: 0 | G26: =G25 -> Pool 1 vs 2 | H26: =D25 -> 0 | I26: =B26 -> 0 | K26: Pool 2 vs 7 | L26: =H26 -> 0 | M26: =H31 -> 0 | O26: 2 vs 3 | P26: =L26 -> 0 | Q26: =L27 -> 0
A27: =A16 -> Pool 3 | B27: {=TRANSPOSE(Groups!D12:D15)} -> 0 | C27: 0 | D27: 0 | E27: 0 | G27: Pool 3 vs 4 | H27: =B27 -> 0 | I27: =D28 -> 0 | K27: Pool 3 vs 6 | L27: =H27 -> 0 | M27: =H30 -> 0
A28: =A17 -> Pool 4 | B28: {=TRANSPOSE(Groups!E12:E15)} -> 0 | C28: 0 | D28: 0 | E28: 0 | G28: =G27 -> Pool 3 vs 4 | H28: =D27 -> 0 | I28: =B28 -> 0 | K28: Pool 4 vs 5 | L28: =H28 -> 0 | M28: =H29 -> 0
A29: =A18 -> Pool 5 | B29: {=TRANSPOSE(Groups!F12:F15)} -> 0 | C29: 0 | D29: 0 | E29: 0 | G29: Pool 5 vs 6 | H29: =B29 -> 0 | I29: =D30 -> 0
A30: =A19 -> Pool 6 | B30: {=TRANSPOSE(Groups!G12:G15)} -> 0 | C30: 0 | D30: 0 | E30: 0 | G30: =G29 -> Pool 5 vs 6 | H30: =D29 -> 0 | I30: =B30 -> 0
A31: =A20 -> Pool 7 | B31: {=TRANSPOSE(Groups!H12:H15)} -> 0 | C31: 0 | D31: 0 | E31: 0 | G31: Pool 7 vs 8 | H31: =B31 -> 0 | I31: =D32 -> 0
A32: =A21 -> Pool 8 | B32: {=TRANSPOSE(Groups!I12:I15)} -> 0 | C32: 0 | D32: 0 | E32: 0 | G32: =G31 -> Pool 7 vs 8 | H32: =D31 -> 0 | I32: =B32 -> 0
A34: Open Mixed Doubles
A35: =A24 -> Group Stage | H35: Pre-Quarters | L35: Quarters | P35: Semis | T35: Finals
A36: =A25 -> Pool 1 | B36: {=TRANSPOSE(Groups!B17:B20)} -> 0 | C36: 0 | D36: 0 | E36: 0 | G36: Pool 1 vs 2 | H36: =B36 -> 0 | I36: =D37 -> 0 | K36: Pool 1 vs 6 | L36: =H36 -> 0 | M36: =H41 -> 0 | O36: 1 vs 4 | P36: =L36 -> 0 | Q36: =L38 -> 0 | S36: 1 vs 2 | T36: =P36 -> 0 | U36: =P37 -> 0
A37: =A26 -> Pool 2 | B37: {=TRANSPOSE(Groups!C17:C20)} -> 0 | C37: 0 | D37: 0 | E37: 0 | G37: =G36 -> Pool 1 vs 2 | H37: =D36 -> 0 | I37: =B37 -> 0 | K37: Pool 2 vs 5 | L37: =H37 -> 0 | M37: =H40 -> 0 | O37: 2 vs 3 | P37: =L37 -> 0 | Q37: WC 1
A38: =A27 -> Pool 3 | B38: {=TRANSPOSE(Groups!D17:D20)} -> 0 | C38: 0 | D38: 0 | E38: 0 | G38: Pool 3 vs 4 | H38: =B38 -> 0 | I38: =D39 -> 0 | K38: Pool 3 vs 4 | L38: =H38 -> 0 | M38: =H39 -> 0
A39: =A28 -> Pool 4 | B39: {=TRANSPOSE(Groups!E17:E20)} -> 0 | C39: 0 | D39: 0 | E39: 0 | G39: =G38 -> Pool 3 vs 4 | H39: =D38 -> 0 | I39: =B39 -> 0
A40: =A29 -> Pool 5 | B40: {=TRANSPOSE(Groups!F17:F20)} -> 0 | C40: 0 | D40: 0 | E40: 0 | G40: Pool 5 vs 6 | H40: =B40 -> 0 | I40: =D41 -> 0
A41: =A30 -> Pool 6 | B41: {=TRANSPOSE(Groups!G17:G20)} -> 0 | C41: 0 | D41: 0 | E41: 0 | G41: =G40 -> Pool 5 vs 6 | H41: =D40 -> 0 | I41: =B41 -> 0
A42: =A31 -> Pool 7
A43: =A32 -> Pool 8
...

Sheet Schedule
A1: Category | B1: Venue | C1: Start Time | D1: End Time | E1: Round Name | F1: Court No | G1: Pool No | H1: Match Details | I1: Player 1 | J1: Player 2 | K1: Team 1 Name | L1: Team 1 Score | M1: Team 1 Outcome | N1: Player 3 | O1: Player 4 | P1: Team 2 Name | Q1: Team 2 Score | R1: Team 2 Outcome | S1: TeamA_Code | T1: TeamB_Code | U1: Colour Legend
A2: Open Men Singles | B2: Adda | C2: 46117.292 | D2: =C2+TIME(0,7,0) -> 46117.297 | E2: Group | F2: 1 | G2: 1 | H2: =IF(OR(S2="",T2=""),"",IFERROR(_xludf.XLOOKUP(S2,'Registrations'!#REF!,'Registrations'!#REF!,_xludf.XLOOKUP(S2,'Registrations'!$B$4:$B$211,'Registrations'!$E$4:$E$211,S2)),S2) & " vs " & IFERROR(_xludf.XLOOKUP(T2,'Registrations'!#REF!,'Registrations'!#REF!,_xludf.XLOOKUP(T2,'Registrations'!$B$4:$B$211,'Registrations'!$E$4:$E$211,T2)),T2)) -> Sanjay Gatti vs 0 | I2: =_xlfn.TEXTBEFORE(H2," vs ") -> Sanjay Gatti | J2: =_xlfn.TEXTAFTER(H2," vs ") -> 0 | K2: =Schedules[[#This Row],[Player 1]] -> Sanjay Gatti | L2: 15 | M2: =IF(L2=15,"WIN","LOST") -> WIN | P2: =Schedules[[#This Row],[Player 2]] -> 0 | Q2: 10 | R2: =IF(Q2=15,"WIN","LOST") -> LOST | S2: =Input!B3 -> Sanjay Gatti | T2: =Input!C3 -> 0 | U2: Group
A3: Open Men Singles | B3: =B2 -> Adda | C3: =C2 -> 46117.292 | D3: =D2 -> 46117.297 | E3: =E2 -> Group | F3: 2 | G3: 2 | H3: =IF(OR(S3="",T3=""),"",IFERROR(_xludf.XLOOKUP(S3,'Registrations'!#REF!,'Registrations'!#REF!,_xludf.XLOOKUP(S3,'Registrations'!$B$4:$B$211,'Registrations'!$E$4:$E$211,S3)),S3) & " vs " & IFERROR(_xludf.XLOOKUP(T3,'Registrations'!#REF!,'Registrations'!#REF!,_xludf.XLOOKUP(T3,'Registrations'!$B$4:$B$211,'Registrations'!$E$4:$E$211,T3)),T3)) -> 0 vs 0 | I3: =_xlfn.TEXTBEFORE(H3," vs ") -> 0 | J3: =_xlfn.TEXTAFTER(H3," vs ") -> 0 | K3: =Schedules[[#This Row],[Player 1]] -> 0 | L3: 15 | M3: =IF(L3=15,"WIN","LOST") -> WIN | P3: =Schedules[[#This Row],[Player 2]] -> 0 | Q3: 10 | R3: =IF(Q3=15,"WIN","LOST") -> LOST | S3: =Input!B4 -> 0 | T3: =Input!C4 -> 0 | U3: Pre-Quarters
A4: Open Men Singles | B4: =B3 -> Adda | C4: =D3+TIME(0,3,0) -> 46117.299 | D4: =C4+TIME(0,7,0) -> 46117.303 | E4: =E3 -> Group | F4: =F2 -> 1 | G4: =G2 -> 1 | H4: =IF(OR(S4="",T4=""),"",IFERROR(_xludf.XLOOKUP(S4,'Registrations'!#REF!,'Registrations'!#REF!,_xludf.XLOOKUP(S4,'Registrations'!$B$4:$B$211,'Registrations'!$E$4:$E$211,S4)),S4) & " vs " & IFERROR(_xludf.XLOOKUP(T4,'Registrations'!#REF!,'Registrations'!#REF!,_xludf.XLOOKUP(T4,'Registrations'!$B$4:$B$211,'Registrations'!$E$4:$E$211,T4)),T4)) -> 0 vs 0 | I4: =_xlfn.TEXTBEFORE(H4," vs ") -> 0 | J4: =_xlfn.TEXTAFTER(H4," vs ") -> 0 | K4: =Schedules[[#This Row],[Player 1]] -> 0 | L4: 15 | M4: =IF(L4=15,"WIN","LOST") -> WIN | P4: =Schedules[[#This Row],[Player 2]] -> 0 | Q4: 10 | R4: =IF(Q4=15,"WIN","LOST") -> LOST | S4: =Input!D3 -> 0 | T4: =Input!E3 -> 0 | U4: Quarters
A5: Open Men Singles | B5: =B4 -> Adda | C5: =C4 -> 46117.299 | D5: =D4 -> 46117.303 | E5: =E4 -> Group | F5: =F3 -> 2 | G5: =G3 -> 2 | H5: =IF(OR(S4="",T4=""),"",IFERROR(_xludf.XLOOKUP(S4,'Registrations'!#REF!,'Registrations'!#REF!,_xludf.XLOOKUP(S4,'Registrations'!$B$4:$B$211,'Registrations'!$E$4:$E$211,S4)),S4) & " vs " & IFERROR(_xludf.XLOOKUP(T4,'Registrations'!#REF!,'Registrations'!#REF!,_xludf.XLOOKUP(T4,'Registrations'!$B$4:$B$211,'Registrations'!$E$4:$E$211,T4)),T4)) -> 0 vs 0 | I5: =_xlfn.TEXTBEFORE(H5," vs ") -> 0 | J5: =_xlfn.TEXTAFTER(H5," vs ") -> 0 | K5: =Schedules[[#This Row],[Player 1]] -> 0 | L5: 15 | M5: =IF(L5=15,"WIN","LOST") -> WIN | P5: =Schedules[[#This Row],[Player 2]] -> 0 | Q5: 10 | R5: =IF(Q5=15,"WIN","LOST") -> LOST | S5: =Input!D4 -> 0 | T5: =Input!E4 -> 0 | U5: Semis
A6: Open Men Singles | B6: =B5 -> Adda | C6: =D5+TIME(0,3,0) -> 46117.306 | D6: =C6+TIME(0,7,0) -> 46117.31 | E6: =E5 -> Group | F6: =F4 -> 1 | G6: =G4 -> 1 | H6: =IF(OR(S5="",T5=""),"",IFERROR(_xludf.XLOOKUP(S5,'Registrations'!#REF!,'Registrations'!#REF!,_xludf.XLOOKUP(S5,'Registrations'!$B$4:$B$211,'Registrations'!$E$4:$E$211,S5)),S5) & " vs " & IFERROR(_xludf.XLOOKUP(T5,'Registrations'!#REF!,'Registrations'!#REF!,_xludf.XLOOKUP(T5,'Registrations'!$B$4:$B$211,'Registrations'!$E$4:$E$211,T5)),T5)) -> 0 vs 0 | I6: =_xlfn.TEXTBEFORE(H6," vs ") -> 0 | J6: =_xlfn.TEXTAFTER(H6," vs ") -> 0 | K6: =Schedules[[#This Row],[Player 1]] -> 0 | L6: 15 | M6: =IF(L6=15,"WIN","LOST") -> WIN | P6: =Schedules[[#This Row],[Player 2]] -> 0 | Q6: 10 | R6: =IF(Q6=15,"WIN","LOST") -> LOST | S6: =Input!B3 -> Sanjay Gatti | T6: =Input!D3 -> 0 | U6: Finals
A7: Open Men Singles | B7: =B6 -> Adda | C7: =C6 -> 46117.306 | D7: =D6 -> 46117.31 | E7: =E6 -> Group | F7: =F5 -> 2 | G7: =G5 -> 2 | H7: =IF(OR(S7="",T7=""),"",IFERROR(_xludf.XLOOKUP(S7,'Registrations'!#REF!,'Registrations'!#REF!,_xludf.XLOOKUP(S7,'Registrations'!$B$4:$B$211,'Registrations'!$E$4:$E$211,S7)),S7) & " vs " & IFERROR(_xludf.XLOOKUP(T7,'Registrations'!#REF!,'Registrations'!#REF!,_xludf.XLOOKUP(T7,'Registrations'!$B$4:$B$211,'Registrations'!$E$4:$E$211,T7)),T7)) -> 0 vs 0 | I7: =_xlfn.TEXTBEFORE(H7," vs ") -> 0 | J7: =_xlfn.TEXTAFTER(H7," vs ") -> 0 | K7: =Schedules[[#This Row],[Player 1]] -> 0 | L7: 15 | M7: =IF(L7=15,"WIN","LOST") -> WIN | P7: =Schedules[[#This Row],[Player 2]] -> 0 | Q7: 10 | R7: =IF(Q7=15,"WIN","LOST") -> LOST | S7: =Input!B4 -> 0 | T7: =Input!D4 -> 0 | U7: Warm-up
A8: Open Men Singles | B8: =B7 -> Adda | C8: =D7+TIME(0,3,0) -> 46117.312 | D8: =C8+TIME(0,7,0) -> 46117.317 | E8: =E7 -> Group | F8: =F6 -> 1 | G8: =G6 -> 1 | H8: =IF(OR(S8="",T8=""),"",IFERROR(_xludf.XLOOKUP(S8,'Registrations'!#REF!,'Registrations'!#REF!,_xludf.XLOOKUP(S8,'Registrations'!$B$4:$B$211,'Registrations'!$E$4:$E$211,S8)),S8) & " vs " & IFERROR(_xludf.XLOOKUP(T8,'Registrations'!#REF!,'Registrations'!#REF!,_xludf.XLOOKUP(T8,'Registrations'!$B$4:$B$211,'Registrations'!$E$4:$E$211,T8)),T8)) -> 0 vs 0 | I8: =_xlfn.TEXTBEFORE(H8," vs ") -> 0 | J8: =_xlfn.TEXTAFTER(H8," vs ") -> 0 | K8: =Schedules[[#This Row],[Player 1]] -> 0 | L8: 15 | M8: =IF(L8=15,"WIN","LOST") -> WIN | P8: =Schedules[[#This Row],[Player 2]] -> 0 | Q8: 10 | R8: =IF(Q8=15,"WIN","LOST") -> LOST | S8: =Input!C3 -> 0 | T8: =Input!E3 -> 0
A9: Open Men Singles | B9: =B8 -> Adda | C9: =C8 -> 46117.312 | D9: =D8 -> 46117.317 | E9: =E8 -> Group | F9: =F7 -> 2 | G9: =G7 -> 2 | H9: =IF(OR(S9="",T9=""),"",IFERROR(_xludf.XLOOKUP(S9,'Registrations'!#REF!,'Registrations'!#REF!,_xludf.XLOOKUP(S9,'Registrations'!$B$4:$B$211,'Registrations'!$E$4:$E$211,S9)),S9) & " vs " & IFERROR(_xludf.XLOOKUP(T9,'Registrations'!#REF!,'Registrations'!#REF!,_xludf.XLOOKUP(T9,'Registrations'!$B$4:$B$211,'Registrations'!$E$4:$E$211,T9)),T9)) -> 0 vs 0 | I9: =_xlfn.TEXTBEFORE(H9," vs ") -> 0 | J9: =_xlfn.TEXTAFTER(H9," vs ") -> 0 | K9: =Schedules[[#This Row],[Player 1]] -> 0 | L9: 15 | M9: =IF(L9=15,"WIN","LOST") -> WIN | P9: =Schedules[[#This Row],[Player 2]] -> 0 | Q9: 10 | R9: =IF(Q9=15,"WIN","LOST") -> LOST | S9: =Input!C4 -> 0 | T9: =Input!E4 -> 0
A10: Open Men Singles | B10: =B9 -> Adda | C10: =D9+TIME(0,3,0) -> 46117.319 | D10: =C10+TIME(0,7,0) -> 46117.324 | E10: =E9 -> Group | F10: =F8 -> 1 | G10: =G8 -> 1 | H10: =IF(OR(S10="",T10=""),"",IFERROR(_xludf.XLOOKUP(S10,'Registrations'!#REF!,'Registrations'!#REF!,_xludf.XLOOKUP(S10,'Registrations'!$B$4:$B$211,'Registrations'!$E$4:$E$211,S10)),S10) & " vs " & IFERROR(_xludf.XLOOKUP(T10,'Registrations'!#REF!,'Registrations'!#REF!,_xludf.XLOOKUP(T10,'Registrations'!$B$4:$B$211,'Registrations'!$E$4:$E$211,T10)),T10)) -> Sanjay Gatti vs 0 | I10: =_xlfn.TEXTBEFORE(H10," vs ") -> Sanjay Gatti | J10: =_xlfn.TEXTAFTER(H10," vs ") -> 0 | K10: =Schedules[[#This Row],[Player 1]] -> Sanjay Gatti | L10: 15 | M10: =IF(L10=15,"WIN","LOST") -> WIN | P10: =Schedules[[#This Row],[Player 2]] -> 0 | Q10: 10 | R10: =IF(Q10=15,"WIN","LOST") -> LOST | S10: =Input!B3 -> Sanjay Gatti | T10: =Input!E3 -> 0
A11: Open Men Singles | B11: =B10 -> Adda | C11: =C10 -> 46117.319 | D11: =D10 -> 46117.324 | E11: =E10 -> Group | F11: =F9 -> 2 | G11: =G9 -> 2 | H11: =IF(OR(S11="",T11=""),"",IFERROR(_xludf.XLOOKUP(S11,'Registrations'!#REF!,'Registrations'!#REF!,_xludf.XLOOKUP(S11,'Registrations'!$B$4:$B$211,'Registrations'!$E$4:$E$211,S11)),S11) & " vs " & IFERROR(_xludf.XLOOKUP(T11,'Registrations'!#REF!,'Registrations'!#REF!,_xludf.XLOOKUP(T11,'Registrations'!$B$4:$B$211,'Registrations'!$E$4:$E$211,T11)),T11)) -> 0 vs 0 | I11: =_xlfn.TEXTBEFORE(H11," vs ") -> 0 | J11: =_xlfn.TEXTAFTER(H11," vs ") -> 0 | K11: =Schedules[[#This Row],[Player 1]] -> 0 | L11: 15 | M11: =IF(L11=15,"WIN","LOST") -> WIN | P11: =Schedules[[#This Row],[Player 2]] -> 0 | Q11: 10 | R11: =IF(Q11=15,"WIN","LOST") -> LOST | S11: =Input!B4 -> 0 | T11: =Input!E4 -> 0
A12: Open Men Singles | B12: =B11 -> Adda | C12: =D11+TIME(0,3,0) -> 46117.326 | D12: =C12+TIME(0,7,0) -> 46117.331 | E12: =E11 -> Group | F12: =F10 -> 1 | G12: =G10 -> 1 | H12: =IF(OR(S12="",T12=""),"",IFERROR(_xludf.XLOOKUP(S12,'Registrations'!#REF!,'Registrations'!#REF!,_xludf.XLOOKUP(S12,'Registrations'!$B$4:$B$211,'Registrations'!$E$4:$E$211,S12)),S12) & " vs " & IFERROR(_xludf.XLOOKUP(T12,'Registrations'!#REF!,'Registrations'!#REF!,_xludf.XLOOKUP(T12,'Registrations'!$B$4:$B$211,'Registrations'!$E$4:$E$211,T12)),T12)) -> 0 vs 0 | I12: =_xlfn.TEXTBEFORE(H12," vs ") -> 0 | J12: =_xlfn.TEXTAFTER(H12," vs ") -> 0 | K12: =Schedules[[#This Row],[Player 1]] -> 0 | L12: 15 | M12: =IF(L12=15,"WIN","LOST") -> WIN | P12: =Schedules[[#This Row],[Player 2]] -> 0 | Q12: 10 | R12: =IF(Q12=15,"WIN","LOST") -> LOST | S12: =Input!C3 -> 0 | T12: =Input!D3 -> 0
A13: Open Men Singles | B13: =B12 -> Adda | C13: =C12 -> 46117.326 | D13: =D12 -> 46117.331 | E13: =E12 -> Group | F13: =F11 -> 2 | G13: =G11 -> 2 | H13: =IF(OR(S13="",T13=""),"",IFERROR(_xludf.XLOOKUP(S13,'Registrations'!#REF!,'Registrations'!#REF!,_xludf.XLOOKUP(S13,'Registrations'!$B$4:$B$211,'Registrations'!$E$4:$E$211,S13)),S13) & " vs " & IFERROR(_xludf.XLOOKUP(T13,'Registrations'!#REF!,'Registrations'!#REF!,_xludf.XLOOKUP(T13,'Registrations'!$B$4:$B$211,'Registrations'!$E$4:$E$211,T13)),T13)) -> 0 vs 0 | I13: =_xlfn.TEXTBEFORE(H13," vs ") -> 0 | J13: =_xlfn.TEXTAFTER(H13," vs ") -> 0 | K13: =Schedules[[#This Row],[Player 1]] -> 0 | L13: 15 | M13: =IF(L13=15,"WIN","LOST") -> WIN | P13: =Schedules[[#This Row],[Player 2]] -> 0 | Q13: 10 | R13: =IF(Q13=15,"WIN","LOST") -> LOST | S13: =Input!C4 -> 0 | T13: =Input!D4 -> 0
A14: Open Men Singles | B14: =B13 -> Adda | C14: =D13+TIME(0,3,0) -> 46117.333 | D14: =C14+TIME(0,7,0) -> 46117.338 | E14: Pre-Q | F14: =F12 -> 1 | G14: 1 vs 2 | H14: =IF(OR(S14="",T14=""),"",IFERROR(_xludf.XLOOKUP(S14,'Registrations'!#REF!,'Registrations'!#REF!,_xludf.XLOOKUP(S14,'Registrations'!$B$4:$B$211,'Registrations'!$E$4:$E$211,S14)),S14) & " vs " & IFERROR(_xludf.XLOOKUP(T14,'Registrations'!#REF!,'Registrations'!#REF!,_xludf.XLOOKUP(T14,'Registrations'!$B$4:$B$211,'Registrations'!$E$4:$E$211,T14)),T14)) -> Sanjay Gatti vs 0 | I14: =_xlfn.TEXTBEFORE(H14," vs ") -> Sanjay Gatti | J14: =_xlfn.TEXTAFTER(H14," vs ") -> 0 | K14: =Schedules[[#This Row],[Player 1]] -> Sanjay Gatti | L14: 15 | M14: =IF(L14=15,"WIN","LOST") -> WIN | P14: =Schedules[[#This Row],[Player 2]] -> 0 | Q14: 10 | R14: =IF(Q14=15,"WIN","LOST") -> LOST | S14: =Input!H3 -> Sanjay Gatti | T14: =Input!I3 -> 0
A15: Open Men Singles | B15: =B14 -> Adda | C15: =C14 -> 46117.333 | D15: =D14 -> 46117.338 | E15: =E14 -> Pre-Q | F15: =F13 -> 2 | G15: 1 vs 2 | H15: =IF(OR(S15="",T15=""),"",IFERROR(_xludf.XLOOKUP(S15,'Registrations'!#REF!,'Registrations'!#REF!,_xludf.XLOOKUP(S15,'Registrations'!$B$4:$B$211,'Registrations'!$E$4:$E$211,S15)),S15) & " vs " & IFERROR(_xludf.XLOOKUP(T15,'Registrations'!#REF!,'Registrations'!#REF!,_xludf.XLOOKUP(T15,'Registrations'!$B$4:$B$211,'Registrations'!$E$4:$E$211,T15)),T15)) -> 0 vs 0 | I15: =_xlfn.TEXTBEFORE(H15," vs ") -> 0 | J15: =_xlfn.TEXTAFTER(H15," vs ") -> 0 | K15: =Schedules[[#This Row],[Player 1]] -> 0 | L15: 15 | M15: =IF(L15=15,"WIN","LOST") -> WIN | P15: =Schedules[[#This Row],[Player 2]] -> 0 | Q15: 10 | R15: =IF(Q15=15,"WIN","LOST") -> LOST | S15: =Input!H4 -> 0 | T15: =Input!I4 -> 0
A16: Open Men Singles | B16: =B15 -> Adda | C16: =D15+TIME(0,3,0) -> 46117.34 | D16: =C16+TIME(0,7,0) -> 46117.345 | E16: Group | F16: =F14 -> 1 | G16: 3 | H16: =IF(OR(S16="",T16=""),"",IFERROR(_xludf.XLOOKUP(S16,'Registrations'!#REF!,'Registrations'!#REF!,_xludf.XLOOKUP(S16,'Registrations'!$B$4:$B$211,'Registrations'!$E$4:$E$211,S16)),S16) & " vs " & IFERROR(_xludf.XLOOKUP(T16,'Registrations'!#REF!,'Registrations'!#REF!,_xludf.XLOOKUP(T16,'Registrations'!$B$4:$B$211,'Registrations'!$E$4:$E$211,T16)),T16)) -> 0 vs 0 | I16: =_xlfn.TEXTBEFORE(H16," vs ") -> 0 | J16: =_xlfn.TEXTAFTER(H16," vs ") -> 0 | K16: =Schedules[[#This Row],[Player 1]] -> 0 | L16: 15 | M16: =IF(L16=15,"WIN","LOST") -> WIN | P16: =Schedules[[#This Row],[Player 2]] -> 0 | Q16: 10 | R16: =IF(Q16=15,"WIN","LOST") -> LOST | S16: =Input!B5 -> 0 | T16: =Input!C5 -> 0
A17: Open Men Singles | B17: =B16 -> Adda | C17: =C16 -> 46117.34 | D17: =D16 -> 46117.345 | E17: =E16 -> Group | F17: =F15 -> 2 | G17: 4 | H17: =IF(OR(S17="",T17=""),"",IFERROR(_xludf.XLOOKUP(S17,'Registrations'!#REF!,'Registrations'!#REF!,_xludf.XLOOKUP(S17,'Registrations'!$B$4:$B$211,'Registrations'!$E$4:$E$211,S17)),S17) & " vs " & IFERROR(_xludf.XLOOKUP(T17,'Registrations'!#REF!,'Registrations'!#REF!,_xludf.XLOOKUP(T17,'Registrations'!$B$4:$B$211,'Registrations'!$E$4:$E$211,T17)),T17)) -> 0 vs 0 | I17: =_xlfn.TEXTBEFORE(H17," vs ") -> 0 | J17: =_xlfn.TEXTAFTER(H17," vs ") -> 0 | K17: =Schedules[[#This Row],[Player 1]] -> 0 | L17: 15 | M17: =IF(L17=15,"WIN","LOST") -> WIN | P17: =Schedules[[#This Row],[Player 2]] -> 0 | Q17: 10 | R17: =IF(Q17=15,"WIN","LOST") -> LOST | S17: =Input!B6 -> 0 | T17: =Input!C6 -> 0
A18: Open Men Singles | B18: =B17 -> Adda | C18: =D17+TIME(0,3,0) -> 46117.347 | D18: =C18+TIME(0,7,0) -> 46117.352 | E18: =E17 -> Group | F18: =F16 -> 1 | G18: =G16 -> 3 | H18: =IF(OR(S18="",T18=""),"",IFERROR(_xludf.XLOOKUP(S18,'Registrations'!#REF!,'Registrations'!#REF!,_xludf.XLOOKUP(S18,'Registrations'!$B$4:$B$211,'Registrations'!$E$4:$E$211,S18)),S18) & " vs " & IFERROR(_xludf.XLOOKUP(T18,'Registrations'!#REF!,'Registrations'!#REF!,_xludf.XLOOKUP(T18,'Registrations'!$B$4:$B$211,'Registrations'!$E$4:$E$211,T18)),T18)) -> 0 vs 0 | I18: =_xlfn.TEXTBEFORE(H18," vs ") -> 0 | J18: =_xlfn.TEXTAFTER(H18," vs ") -> 0 | K18: =Schedules[[#This Row],[Player 1]] -> 0 | L18: 15 | M18: =IF(L18=15,"WIN","LOST") -> WIN | P18: =Schedules[[#This Row],[Player 2]] -> 0 | Q18: 10 | R18: =IF(Q18=15,"WIN","LOST") -> LOST | S18: =Input!D5 -> 0 | T18: =Input!E5 -> 0
A19: Open Men Singles | B19: =B18 -> Adda | C19: =C18 -> 46117.347 | D19: =D18 -> 46117.352 | E19: =E18 -> Group | F19: =F17 -> 2 | G19: =G17 -> 4 | H19: =IF(OR(S19="",T19=""),"",IFERROR(_xludf.XLOOKUP(S19,'Registrations'!#REF!,'Registrations'!#REF!,_xludf.XLOOKUP(S19,'Registrations'!$B$4:$B$211,'Registrations'!$E$4:$E$211,S19)),S19) & " vs " & IFERROR(_xludf.XLOOKUP(T19,'Registrations'!#REF!,'Registrations'!#REF!,_xludf.XLOOKUP(T19,'Registrations'!$B$4:$B$211,'Registrations'!$E$4:$E$211,T19)),T19)) -> 0 vs 0 | I19: =_xlfn.TEXTBEFORE(H19," vs ") -> 0 | J19: =_xlfn.TEXTAFTER(H19," vs ") -> 0 | K19: =Schedules[[#This Row],[Player 1]] -> 0 | L19: 15 | M19: =IF(L19=15,"WIN","LOST") -> WIN | P19: =Schedules[[#This Row],[Player 2]] -> 0 | Q19: 10 | R19: =IF(Q19=15,"WIN","LOST") -> LOST | S19: =Input!D6 -> 0 | T19: =Input!E6 -> 0
A20: Open Men Singles | B20: =B19 -> Adda | C20: =D19+TIME(0,3,0) -> 46117.354 | D20: =C20+TIME(0,7,0) -> 46117.359 | E20: =E19 -> Group | F20: =F18 -> 1 | G20: =G18 -> 3 | H20: =IF(OR(S20="",T20=""),"",IFERROR(_xludf.XLOOKUP(S20,'Registrations'!#REF!,'Registrations'!#REF!,_xludf.XLOOKUP(S20,'Registrations'!$B$4:$B$211,'Registrations'!$E$4:$E$211,S20)),S20) & " vs " & IFERROR(_xludf.XLOOKUP(T20,'Registrations'!#REF!,'Registrations'!#REF!,_xludf.XLOOKUP(T20,'Registrations'!$B$4:$B$211,'Registrations'!$E$4:$E$211,T20)),T20)) -> 0 vs 0 | I20: =_xlfn.TEXTBEFORE(H20," vs ") -> 0 | J20: =_xlfn.TEXTAFTER(H20," vs ") -> 0 | K20: =Schedules[[#This Row],[Player 1]] -> 0 | L20: 15 | M20: =IF(L20=15,"WIN","LOST") -> WIN | P20: =Schedules[[#This Row],[Player 2]] -> 0 | Q20: 10 | R20: =IF(Q20=15,"WIN","LOST") -> LOST | S20: =Input!B5 -> 0 | T20: =Input!D5 -> 0
A21: Open Men Singles | B21: =B20 -> Adda | C21: =C20 -> 46117.354 | D21: =D20 -> 46117.359 | E21: Group | F21: =F19 -> 2 | G21: =G19 -> 4 | H21: =IF(OR(S21="",T21=""),"",IFERROR(_xludf.XLOOKUP(S21,'Registrations'!#REF!,'Registrations'!#REF!,_xludf.XLOOKUP(S21,'Registrations'!$B$4:$B$211,'Registrations'!$E$4:$E$211,S21)),S21) & " vs " & IFERROR(_xludf.XLOOKUP(T21,'Registrations'!#REF!,'Registrations'!#REF!,_xludf.XLOOKUP(T21,'Registrations'!$B$4:$B$211,'Registrations'!$E$4:$E$211,T21)),T21)) -> 0 vs 0 | I21: =_xlfn.TEXTBEFORE(H21," vs ") -> 0 | J21: =_xlfn.TEXTAFTER(H21," vs ") -> 0 | K21: =Schedules[[#This Row],[Player 1]] -> 0 | L21: 15 | M21: =IF(L21=15,"WIN","LOST") -> WIN | P21: =Schedules[[#This Row],[Player 2]] -> 0 | Q21: 10 | R21: =IF(Q21=15,"WIN","LOST") -> LOST | S21: =Input!B6 -> 0 | T21: =Input!D6 -> 0
A22: Open Men Singles | B22: =B21 -> Adda | C22: =D21+TIME(0,3,0) -> 46117.361 | D22: =C22+TIME(0,7,0) -> 46117.366 | E22: =E21 -> Group | F22: =F20 -> 1 | G22: =G20 -> 3 | H22: =IF(OR(S22="",T22=""),"",IFERROR(_xludf.XLOOKUP(S22,'Registrations'!#REF!,'Registrations'!#REF!,_xludf.XLOOKUP(S22,'Registrations'!$B$4:$B$211,'Registrations'!$E$4:$E$211,S22)),S22) & " vs " & IFERROR(_xludf.XLOOKUP(T22,'Registrations'!#REF!,'Registrations'!#REF!,_xludf.XLOOKUP(T22,'Registrations'!$B$4:$B$211,'Registrations'!$E$4:$E$211,T22)),T22)) -> 0 vs 0 | I22: =_xlfn.TEXTBEFORE(H22," vs ") -> 0 | J22: =_xlfn.TEXTAFTER(H22," vs ") -> 0 | K22: =Schedules[[#This Row],[Player 1]] -> 0 | L22: 15 | M22: =IF(L22=15,"WIN","LOST") -> WIN | P22: =Schedules[[#This Row],[Player 2]] -> 0 | Q22: 10 | R22: =IF(Q22=15,"WIN","LOST") -> LOST | S22: =Input!C5 -> 0 | T22: =Input!E5 -> 0
A23: Open Men Singles | B23: =B22 -> Adda | C23: =C22 -> 46117.361 | D23: =D22 -> 46117.366 | E23: =E22 -> Group | F23: =F21 -> 2 | G23: =G21 -> 4 | H23: =IF(OR(S23="",T23=""),"",IFERROR(_xludf.XLOOKUP(S23,'Registrations'!#REF!,'Registrations'!#REF!,_xludf.XLOOKUP(S23,'Registrations'!$B$4:$B$211,'Registrations'!$E$4:$E$211,S23)),S23) & " vs " & IFERROR(_xludf.XLOOKUP(T23,'Registrations'!#REF!,'Registrations'!#REF!,_xludf.XLOOKUP(T23,'Registrations'!$B$4:$B$211,'Registrations'!$E$4:$E$211,T23)),T23)) -> 0 vs 0 | I23: =_xlfn.TEXTBEFORE(H23," vs ") -> 0 | J23: =_xlfn.TEXTAFTER(H23," vs ") -> 0 | K23: =Schedules[[#This Row],[Player 1]] -> 0 | L23: 15 | M23: =IF(L23=15,"WIN","LOST") -> WIN | P23: =Schedules[[#This Row],[Player 2]] -> 0 | Q23: 10 | R23: =IF(Q23=15,"WIN","LOST") -> LOST | S23: =Input!C6 -> 0 | T23: =Input!E6 -> 0
A24: Open Men Singles | B24: =B23 -> Adda | C24: =D23+TIME(0,3,0) -> 46117.368 | D24: =C24+TIME(0,7,0) -> 46117.373 | E24: Group | F24: =F22 -> 1 | G24: =G22 -> 3 | H24: =IF(OR(S24="",T24=""),"",IFERROR(_xludf.XLOOKUP(S24,'Registrations'!#REF!,'Registrations'!#REF!,_xludf.XLOOKUP(S24,'Registrations'!$B$4:$B$211,'Registrations'!$E$4:$E$211,S24)),S24) & " vs " & IFERROR(_xludf.XLOOKUP(T24,'Registrations'!#REF!,'Registrations'!#REF!,_xludf.XLOOKUP(T24,'Registrations'!$B$4:$B$211,'Registrations'!$E$4:$E$211,T24)),T24)) -> 0 vs 0 | I24: =_xlfn.TEXTBEFORE(H24," vs ") -> 0 | J24: =_xlfn.TEXTAFTER(H24," vs ") -> 0 | K24: =Schedules[[#This Row],[Player 1]] -> 0 | L24: 15 | M24: =IF(L24=15,"WIN","LOST") -> WIN | P24: =Schedules[[#This Row],[Player 2]] -> 0 | Q24: 10 | R24: =IF(Q24=15,"WIN","LOST") -> LOST | S24: =Input!B5 -> 0 | T24: =Input!E5 -> 0
A25: Open Men Singles | B25: =B24 -> Adda | C25: =C24 -> 46117.368 | D25: =D24 -> 46117.373 | E25: =E24 -> Group | F25: =F23 -> 2 | G25: =G23 -> 4 | H25: =IF(OR(S25="",T25=""),"",IFERROR(_xludf.XLOOKUP(S25,'Registrations'!#REF!,'Registrations'!#REF!,_xludf.XLOOKUP(S25,'Registrations'!$B$4:$B$211,'Registrations'!$E$4:$E$211,S25)),S25) & " vs " & IFERROR(_xludf.XLOOKUP(T25,'Registrations'!#REF!,'Registrations'!#REF!,_xludf.XLOOKUP(T25,'Registrations'!$B$4:$B$211,'Registrations'!$E$4:$E$211,T25)),T25)) -> 0 vs 0 | I25: =_xlfn.TEXTBEFORE(H25," vs ") -> 0 | J25: =_xlfn.TEXTAFTER(H25," vs ") -> 0 | K25: =Schedules[[#This Row],[Player 1]] -> 0 | L25: 15 | M25: =IF(L25=15,"WIN","LOST") -> WIN | P25: =Schedules[[#This Row],[Player 2]] -> 0 | Q25: 10 | R25: =IF(Q25=15,"WIN","LOST") -> LOST | S25: =Input!B6 -> 0 | T25: =Input!E6 -> 0
A26: Open Men Singles | B26: =B25 -> Adda | C26: =D25+TIME(0,3,0) -> 46117.375 | D26: =C26+TIME(0,7,0) -> 46117.38 | E26: =E25 -> Group | F26: =F24 -> 1 | G26: =G24 -> 3 | H26: =IF(OR(S26="",T26=""),"",IFERROR(_xludf.XLOOKUP(S26,'Registrations'!#REF!,'Registrations'!#REF!,_xludf.XLOOKUP(S26,'Registrations'!$B$4:$B$211,'Registrations'!$E$4:$E$211,S26)),S26) & " vs " & IFERROR(_xludf.XLOOKUP(T26,'Registrations'!#REF!,'Registrations'!#REF!,_xludf.XLOOKUP(T26,'Registrations'!$B$4:$B$211,'Registrations'!$E$4:$E$211,T26)),T26)) -> 0 vs 0 | I26: =_xlfn.TEXTBEFORE(H26," vs ") -> 0 | J26: =_xlfn.TEXTAFTER(H26," vs ") -> 0 | K26: =Schedules[[#This Row],[Player 1]] -> 0 | L26: 15 | M26: =IF(L26=15,"WIN","LOST") -> WIN | P26: =Schedules[[#This Row],[Player 2]] -> 0 | Q26: 10 | R26: =IF(Q26=15,"WIN","LOST") -> LOST | S26: =Input!C5 -> 0 | T26: =Input!D5 -> 0
A27: Open Men Singles | B27: =B26 -> Adda | C27: =C26 -> 46117.375 | D27: =D26 -> 46117.38 | E27: =E26 -> Group | F27: =F25 -> 2 | G27: =G25 -> 4 | H27: =IF(OR(S27="",T27=""),"",IFERROR(_xludf.XLOOKUP(S27,'Registrations'!#REF!,'Registrations'!#REF!,_xludf.XLOOKUP(S27,'Registrations'!$B$4:$B$211,'Registrations'!$E$4:$E$211,S27)),S27) & " vs " & IFERROR(_xludf.XLOOKUP(T27,'Registrations'!#REF!,'Registrations'!#REF!,_xludf.XLOOKUP(T27,'Registrations'!$B$4:$B$211,'Registrations'!$E$4:$E$211,T27)),T27)) -> 0 vs 0 | I27: =_xlfn.TEXTBEFORE(H27," vs ") -> 0 | J27: =_xlfn.TEXTAFTER(H27," vs ") -> 0 | K27: =Schedules[[#This Row],[Player 1]] -> 0 | L27: 15 | M27: =IF(L27=15,"WIN","LOST") -> WIN | P27: =Schedules[[#This Row],[Player 2]] -> 0 | Q27: 10 | R27: =IF(Q27=15,"WIN","LOST") -> LOST | S27: =Input!C6 -> 0 | T27: =Input!D6 -> 0
A28: Open Men Singles | B28: =B27 -> Adda | C28: =D27+TIME(0,3,0) -> 46117.382 | D28: =C28+TIME(0,7,0) -> 46117.387 | E28: Pre-Q | F28: =F26 -> 1 | G28: 3 vs 4 | H28: =IF(OR(S28="",T28=""),"",IFERROR(_xludf.XLOOKUP(S28,'Registrations'!#REF!,'Registrations'!#REF!,_xludf.XLOOKUP(S28,'Registrations'!$B$4:$B$211,'Registrations'!$E$4:$E$211,S28)),S28) & " vs " & IFERROR(_xludf.XLOOKUP(T28,'Registrations'!#REF!,'Registrations'!#REF!,_xludf.XLOOKUP(T28,'Registrations'!$B$4:$B$211,'Registrations'!$E$4:$E$211,T28)),T28)) -> 0 vs 0 | I28: =_xlfn.TEXTBEFORE(H28," vs ") -> 0 | J28: =_xlfn.TEXTAFTER(H28," vs ") -> 0 | K28: =Schedules[[#This Row],[Player 1]] -> 0 | L28: 15 | M28: =IF(L28=15,"WIN","LOST") -> WIN | P28: =Schedules[[#This Row],[Player 2]] -> 0 | Q28: 10 | R28: =IF(Q28=15,"WIN","LOST") -> LOST | S28: =Input!H5 -> 0 | T28: =Input!I5 -> 0
A29: Open Men Singles | B29: =B28 -> Adda | C29: =C28 -> 46117.382 | D29: =D28 -> 46117.387 | E29: =E28 -> Pre-Q | F29: =F27 -> 2 | G29: 3 vs 4 | H29: =IF(OR(S29="",T29=""),"",IFERROR(_xludf.XLOOKUP(S29,'Registrations'!#REF!,'Registrations'!#REF!,_xludf.XLOOKUP(S29,'Registrations'!$B$4:$B$211,'Registrations'!$E$4:$E$211,S29)),S29) & " vs " & IFERROR(_xludf.XLOOKUP(T29,'Registrations'!#REF!,'Registrations'!#REF!,_xludf.XLOOKUP(T29,'Registrations'!$B$4:$B$211,'Registrations'!$E$4:$E$211,T29)),T29)) -> 0 vs 0 | I29: =_xlfn.TEXTBEFORE(H29," vs ") -> 0 | J29: =_xlfn.TEXTAFTER(H29," vs ") -> 0 | K29: =Schedules[[#This Row],[Player 1]] -> 0 | L29: 15 | M29: =IF(L29=15,"WIN","LOST") -> WIN | P29: =Schedules[[#This Row],[Player 2]] -> 0 | Q29: 10 | R29: =IF(Q29=15,"WIN","LOST") -> LOST | S29: =Input!H6 -> 0 | T29: =Input!I6 -> 0
A30: Open Men Singles | B30: =B29 -> Adda | C30: =D29+TIME(0,3,0) -> 46117.389 | D30: =C30+TIME(0,7,0) -> 46117.394 | E30: Group | F30: =F28 -> 1 | G30: 5 | H30: =IF(OR(S30="",T30=""),"",IFERROR(_xludf.XLOOKUP(S30,'Registrations'!#REF!,'Registrations'!#REF!,_xludf.XLOOKUP(S30,'Registrations'!$B$4:$B$211,'Registrations'!$E$4:$E$211,S30)),S30) & " vs " & IFERROR(_xludf.XLOOKUP(T30,'Registrations'!#REF!,'Registrations'!#REF!,_xludf.XLOOKUP(T30,'Registrations'!$B$4:$B$211,'Registrations'!$E$4:$E$211,T30)),T30)) -> 0 vs 0 | I30: =_xlfn.TEXTBEFORE(H30," vs ") -> 0 | J30: =_xlfn.TEXTAFTER(H30," vs ") -> 0 | K30: =Schedules[[#This Row],[Player 1]] -> 0 | L30: 15 | M30: =IF(L30=15,"WIN","LOST") -> WIN | P30: =Schedules[[#This Row],[Player 2]] -> 0 | Q30: 10 | R30: =IF(Q30=15,"WIN","LOST") -> LOST | S30: =Input!B7 -> 0 | T30: =Input!C7 -> 0
A31: Open Men Singles | B31: =B30 -> Adda | C31: =C30 -> 46117.389 | D31: =D30 -> 46117.394 | E31: =E30 -> Group | F31: =F29 -> 2 | G31: 6 | H31: =IF(OR(S31="",T31=""),"",IFERROR(_xludf.XLOOKUP(S31,'Registrations'!#REF!,'Registrations'!#REF!,_xludf.XLOOKUP(S31,'Registrations'!$B$4:$B$211,'Registrations'!$E$4:$E$211,S31)),S31) & " vs " & IFERROR(_xludf.XLOOKUP(T31,'Registrations'!#REF!,'Registrations'!#REF!,_xludf.XLOOKUP(T31,'Registrations'!$B$4:$B$211,'Registrations'!$E$4:$E$211,T31)),T31)) -> 0 vs 0 | I31: =_xlfn.TEXTBEFORE(H31," vs ") -> 0 | J31: =_xlfn.TEXTAFTER(H31," vs ") -> 0 | K31: =Schedules[[#This Row],[Player 1]] -> 0 | L31: 15 | M31: =IF(L31=15,"WIN","LOST") -> WIN | P31: =Schedules[[#This Row],[Player 2]] -> 0 | Q31: 10 | R31: =IF(Q31=15,"WIN","LOST") -> LOST | S31: =Input!B8 -> 0 | T31: =Input!C8 -> 0
A32: Open Men Singles | B32: =B31 -> Adda | C32: =D31+TIME(0,3,0) -> 46117.396 | D32: =C32+TIME(0,7,0) -> 46117.401 | E32: =E31 -> Group | F32: =F30 -> 1 | G32: =G30 -> 5 | H32: =IF(OR(S32="",T32=""),"",IFERROR(_xludf.XLOOKUP(S32,'Registrations'!#REF!,'Registrations'!#REF!,_xludf.XLOOKUP(S32,'Registrations'!$B$4:$B$211,'Registrations'!$E$4:$E$211,S32)),S32) & " vs " & IFERROR(_xludf.XLOOKUP(T32,'Registrations'!#REF!,'Registrations'!#REF!,_xludf.XLOOKUP(T32,'Registrations'!$B$4:$B$211,'Registrations'!$E$4:$E$211,T32)),T32)) -> 0 vs 0 | I32: =_xlfn.TEXTBEFORE(H32," vs ") -> 0 | J32: =_xlfn.TEXTAFTER(H32," vs ") -> 0 | K32: =Schedules[[#This Row],[Player 1]] -> 0 | L32: 15 | M32: =IF(L32=15,"WIN","LOST") -> WIN | P32: =Schedules[[#This Row],[Player 2]] -> 0 | Q32: 10 | R32: =IF(Q32=15,"WIN","LOST") -> LOST | S32: =Input!D7 -> 0 | T32: =Input!E7 -> 0
A33: Open Men Singles | B33: =B32 -> Adda | C33: =C32 -> 46117.396 | D33: =D32 -> 46117.401 | E33: =E32 -> Group | F33: =F31 -> 2 | G33: =G31 -> 6 | H33: =IF(OR(S33="",T33=""),"",IFERROR(_xludf.XLOOKUP(S33,'Registrations'!#REF!,'Registrations'!#REF!,_xludf.XLOOKUP(S33,'Registrations'!$B$4:$B$211,'Registrations'!$E$4:$E$211,S33)),S33) & " vs " & IFERROR(_xludf.XLOOKUP(T33,'Registrations'!#REF!,'Registrations'!#REF!,_xludf.XLOOKUP(T33,'Registrations'!$B$4:$B$211,'Registrations'!$E$4:$E$211,T33)),T33)) -> 0 vs 0 | I33: =_xlfn.TEXTBEFORE(H33," vs ") -> 0 | J33: =_xlfn.TEXTAFTER(H33," vs ") -> 0 | K33: =Schedules[[#This Row],[Player 1]] -> 0 | L33: 15 | M33: =IF(L33=15,"WIN","LOST") -> WIN | P33: =Schedules[[#This Row],[Player 2]] -> 0 | Q33: 10 | R33: =IF(Q33=15,"WIN","LOST") -> LOST | S33: =Input!D8 -> 0 | T33: =Input!E8 -> 0
A34: Open Men Singles | B34: =B33 -> Adda | C34: =D33+TIME(0,3,0) -> 46117.403 | D34: =C34+TIME(0,7,0) -> 46117.408 | E34: =E33 -> Group | F34: =F32 -> 1 | G34: =G32 -> 5 | H34: =IF(OR(S34="",T34=""),"",IFERROR(_xludf.XLOOKUP(S34,'Registrations'!#REF!,'Registrations'!#REF!,_xludf.XLOOKUP(S34,'Registrations'!$B$4:$B$211,'Registrations'!$E$4:$E$211,S34)),S34) & " vs " & IFERROR(_xludf.XLOOKUP(T34,'Registrations'!#REF!,'Registrations'!#REF!,_xludf.XLOOKUP(T34,'Registrations'!$B$4:$B$211,'Registrations'!$E$4:$E$211,T34)),T34)) -> 0 vs 0 | I34: =_xlfn.TEXTBEFORE(H34," vs ") -> 0 | J34: =_xlfn.TEXTAFTER(H34," vs ") -> 0 | K34: =Schedules[[#This Row],[Player 1]] -> 0 | L34: 15 | M34: =IF(L34=15,"WIN","LOST") -> WIN | P34: =Schedules[[#This Row],[Player 2]] -> 0 | Q34: 10 | R34: =IF(Q34=15,"WIN","LOST") -> LOST | S34: =Input!B7 -> 0 | T34: =Input!D7 -> 0
A35: Open Men Singles | B35: =B34 -> Adda | C35: =C34 -> 46117.403 | D35: =D34 -> 46117.408 | E35: Group | F35: =F33 -> 2 | G35: =G33 -> 6 | H35: =IF(OR(S35="",T35=""),"",IFERROR(_xludf.XLOOKUP(S35,'Registrations'!#REF!,'Registrations'!#REF!,_xludf.XLOOKUP(S35,'Registrations'!$B$4:$B$211,'Registrations'!$E$4:$E$211,S35)),S35) & " vs " & IFERROR(_xludf.XLOOKUP(T35,'Registrations'!#REF!,'Registrations'!#REF!,_xludf.XLOOKUP(T35,'Registrations'!$B$4:$B$211,'Registrations'!$E$4:$E$211,T35)),T35)) -> 0 vs 0 | I35: =_xlfn.TEXTBEFORE(H35," vs ") -> 0 | J35: =_xlfn.TEXTAFTER(H35," vs ") -> 0 | K35: =Schedules[[#This Row],[Player 1]] -> 0 | L35: 15 | M35: =IF(L35=15,"WIN","LOST") -> WIN | P35: =Schedules[[#This Row],[Player 2]] -> 0 | Q35: 10 | R35: =IF(Q35=15,"WIN","LOST") -> LOST | S35: =Input!B8 -> 0 | T35: =Input!D8 -> 0
A36: Open Men Singles | B36: =B35 -> Adda | C36: =D35+TIME(0,3,0) -> 46117.41 | D36: =C36+TIME(0,7,0) -> 46117.415 | E36: Group | F36: =F34 -> 1 | G36: =G34 -> 5 | H36: =IF(OR(S36="",T36=""),"",IFERROR(_xludf.XLOOKUP(S36,'Registrations'!#REF!,'Registrations'!#REF!,_xludf.XLOOKUP(S36,'Registrations'!$B$4:$B$211,'Registrations'!$E$4:$E$211,S36)),S36) & " vs " & IFERROR(_xludf.XLOOKUP(T36,'Registrations'!#REF!,'Registrations'!#REF!,_xludf.XLOOKUP(T36,'Registrations'!$B$4:$B$211,'Registrations'!$E$4:$E$211,T36)),T36)) -> 0 vs 0 | I36: =_xlfn.TEXTBEFORE(H36," vs ") -> 0 | J36: =_xlfn.TEXTAFTER(H36," vs ") -> 0 | K36: =Schedules[[#This Row],[Player 1]] -> 0 | L36: 15 | M36: =IF(L36=15,"WIN","LOST") -> WIN | P36: =Schedules[[#This Row],[Player 2]] -> 0 | Q36: 10 | R36: =IF(Q36=15,"WIN","LOST") -> LOST | S36: =Input!C7 -> 0 | T36: =Input!E7 -> 0
A37: Open Men Singles | B37: =B36 -> Adda | C37: =C36 -> 46117.41 | D37: =D36 -> 46117.415 | E37: Group | F37: =F35 -> 2 | G37: =G35 -> 6 | H37: =IF(OR(S37="",T37=""),"",IFERROR(_xludf.XLOOKUP(S37,'Registrations'!#REF!,'Registrations'!#REF!,_xludf.XLOOKUP(S37,'Registrations'!$B$4:$B$211,'Registrations'!$E$4:$E$211,S37)),S37) & " vs " & IFERROR(_xludf.XLOOKUP(T37,'Registrations'!#REF!,'Registrations'!#REF!,_xludf.XLOOKUP(T37,'Registrations'!$B$4:$B$211,'Registrations'!$E$4:$E$211,T37)),T37)) -> 0 vs 0 | I37: =_xlfn.TEXTBEFORE(H37," vs ") -> 0 | J37: =_xlfn.TEXTAFTER(H37," vs ") -> 0 | K37: =Schedules[[#This Row],[Player 1]] -> 0 | L37: 15 | M37: =IF(L37=15,"WIN","LOST") -> WIN | P37: =Schedules[[#This Row],[Player 2]] -> 0 | Q37: 10 | R37: =IF(Q37=15,"WIN","LOST") -> LOST | S37: =Input!C8 -> 0 | T37: =Input!E8 -> 0
A38: Open Men Singles | B38: =B37 -> Adda | C38: =D37+TIME(0,3,0) -> 46117.417 | D38: =C38+TIME(0,7,0) -> 46117.422 | E38: Group | F38: =F36 -> 1 | G38: =G36 -> 5 | H38: =IF(OR(S38="",T38=""),"",IFERROR(_xludf.XLOOKUP(S38,'Registrations'!#REF!,'Registrations'!#REF!,_xludf.XLOOKUP(S38,'Registrations'!$B$4:$B$211,'Registrations'!$E$4:$E$211,S38)),S38) & " vs " & IFERROR(_xludf.XLOOKUP(T38,'Registrations'!#REF!,'Registrations'!#REF!,_xludf.XLOOKUP(T38,'Registrations'!$B$4:$B$211,'Registrations'!$E$4:$E$211,T38)),T38)) -> 0 vs 0 | I38: =_xlfn.TEXTBEFORE(H38," vs ") -> 0 | J38: =_xlfn.TEXTAFTER(H38," vs ") -> 0 | K38: =Schedules[[#This Row],[Player 1]] -> 0 | L38: 15 | M38: =IF(L38=15,"WIN","LOST") -> WIN | P38: =Schedules[[#This Row],[Player 2]] -> 0 | Q38: 10 | R38: =IF(Q38=15,"WIN","LOST") -> LOST | S38: =Input!B7 -> 0 | T38: =Input!E7 -> 0
A39: Open Men Singles | B39: =B38 -> Adda | C39: =C38 -> 46117.417 | D39: =D38 -> 46117.422 | E39: =E38 -> Group | F39: =F37 -> 2 | G39: =G37 -> 6 | H39: =IF(OR(S39="",T39=""),"",IFERROR(_xludf.XLOOKUP(S39,'Registrations'!#REF!,'Registrations'!#REF!,_xludf.XLOOKUP(S39,'Registrations'!$B$4:$B$211,'Registrations'!$E$4:$E$211,S39)),S39) & " vs " & IFERROR(_xludf.XLOOKUP(T39,'Registrations'!#REF!,'Registrations'!#REF!,_xludf.XLOOKUP(T39,'Registrations'!$B$4:$B$211,'Registrations'!$E$4:$E$211,T39)),T39)) -> 0 vs 0 | I39: =_xlfn.TEXTBEFORE(H39," vs ") -> 0 | J39: =_xlfn.TEXTAFTER(H39," vs ") -> 0 | K39: =Schedules[[#This Row],[Player 1]] -> 0 | L39: 15 | M39: =IF(L39=15,"WIN","LOST") -> WIN | P39: =Schedules[[#This Row],[Player 2]] -> 0 | Q39: 10 | R39: =IF(Q39=15,"WIN","LOST") -> LOST | S39: =Input!B8 -> 0 | T39: =Input!E8 -> 0
A40: Open Men Singles | B40: =B39 -> Adda | C40: =D39+TIME(0,3,0) -> 46117.424 | D40: =C40+TIME(0,7,0) -> 46117.428 | E40: =E39 -> Group | F40: =F38 -> 1 | G40: =G38 -> 5 | H40: =IF(OR(S40="",T40=""),"",IFERROR(_xludf.XLOOKUP(S40,'Registrations'!#REF!,'Registrations'!#REF!,_xludf.XLOOKUP(S40,'Registrations'!$B$4:$B$211,'Registrations'!$E$4:$E$211,S40)),S40) & " vs " & IFERROR(_xludf.XLOOKUP(T40,'Registrations'!#REF!,'Registrations'!#REF!,_xludf.XLOOKUP(T40,'Registrations'!$B$4:$B$211,'Registrations'!$E$4:$E$211,T40)),T40)) -> 0 vs 0 | I40: =_xlfn.TEXTBEFORE(H40," vs ") -> 0 | J40: =_xlfn.TEXTAFTER(H40," vs ") -> 0 | K40: =Schedules[[#This Row],[Player 1]] -> 0 | L40: 15 | M40: =IF(L40=15,"WIN","LOST") -> WIN | P40: =Schedules[[#This Row],[Player 2]] -> 0 | Q40: 10 | R40: =IF(Q40=15,"WIN","LOST") -> LOST | S40: =Input!C7 -> 0 | T40: =Input!D7 -> 0
...

Sheet PnL
A1: Court Mafia 2.0 - Financial Model
A3: Details | B3: Open Men Singles | C3: Open Veteran Doubles | D3: 45+ Split Doubles | E3: Beginner Men's Doubles | F3: Beginner Mx Doubles | G3: Int Men Doubles | H3: Open Mx Doubles | I3: Adv Men Doubles
A4: No of players | B4: 24 | C4: 0 | D4: 0 | E4: 0 | F4: 0 | G4: 0
A5: No of teams | B5: 0 | C5: 12 | D5: 28 | E5: 24 | F5: 20 | G5: 32 | H5: 28 | I5: 24
A6: Entry fee | B6: 800 | C6: 1600 | D6: 1600 | E6: =D6 -> 1600 | F6: =E6 -> 1600 | G6: =F6 -> 1600 | H6: =G6 -> 1600 | I6: =H6 -> 1600
A7: Fee income | B7: =(B6*B4)+(B6*B5) -> 19200 | C7: =(C6*C4)+(C6*C5) -> 19200 | D7: =(D6*D4)+(D6*D5) -> 44800 | E7: =(E6*E4)+(E6*E5) -> 38400 | F7: =(F6*F4)+(F6*F5) -> 32000 | G7: =(G6*G4)+(G6*G5) -> 51200 | H7: =(H6*H4)+(H6*H5) -> 44800 | I7: =(I6*I4)+(I6*I5) -> 38400
A9: Particulars | B9: Amt (in Rs)
A10: Income:
A11: Entry fees | B11: =SUM(B7:I7) -> 288000
A12: Sponsorship | B12: 30000
A13: Stall rentals | B13: =B14*B15 -> 25000
A14: -No of stalls | B14: 5
A15: -Rent/stall | B15: 5000
A16: Total Income | B16: =SUM(B11:B13) -> 343000
A17: Expense:
A18: Prize pool | B18: 100000
A19: Court charges | B19: =SUM(I32:I37) -> 22800
A20: Balls | B20: =(120*15)+(155*15) -> 4125
A21: Referee | B21: =B22*B23*B24 -> 14400
A22: -No of days | B22: 4
A23: -Per day fee | B23: 1200
A24: -Total referees | B24: 3
A25: Misc | B25: 60000
A26: Total Expense | B26: =SUM(B18:B20,B21,B25) -> 201325
A27: Net Profit | B27: =B16-B26 -> 141675
A30: Court Charges
A31: Day | B31: Venue | C31: Category to be played | D31: Courts | E31: Matches | F31: Slot (min) | G31: Actual Hours | H31: Court/hr | I31: Court cost
A32: 5th April | B32: Gawand Baug | C32: Open Mens Singles | D32: 3 | E32: 48 | F32: 10 | G32: 3 | H32: 400 | I32: =H32*D32*G32 -> 3600
